<?xml version="1.0" ?>
<!-- =================================================================================== -->
<!-- |    This document was autogenerated by xacro from complete_door.xacro            | -->
<!-- |    EDITING THIS FILE BY HAND IS NOT RECOMMENDED                                 | -->
<!-- =================================================================================== -->
<robot xmlns:xacro="http://www.ros.org/wiki/xacro" name="complete door">
  <xacro:arg name="parent" default="world"/>
  <link name="world"/>
  <joint name="door_world" type="revolute">
    <origin xyz="0 0 0" rpy="0 0 0"/>
    <parent link="world"/>
    <child link="door_plane"/>
    <axis xyz="0 0 1"/>
    <dynamics friction="0.01"/>
    <limit lower="0.0" upper="1.57"/>
  </joint>
  <link name="door_plane">
    <visual>
      <origin xyz="0 0.35 0"/>
      <geometry>
        <mesh filename="door2.obj" rpy="0 0 0" scale="1.0 1.0 1.0"/>
      </geometry>
    </visual>
    <collision>
        <origin xyz="0.0 0.35 0.0" />
        <geometry>
            <mesh filename="door2.obj" rpy="0 0 0" scale="1.0 1.0 1.0" />
        </geometry>
    </collision>
  </link>
  <xacro:arg name="handle_pos_x" default="0.0"/>
  <xacro:arg name="handle_pos_y" default="0.0"/>
  <xacro:arg name="handle_pos_z" default="0.0"/>
  <xacro:arg name="handle_ori_r" default="0.0"/>
  <xacro:arg name="handle_ori_p" default="0.0"/>
  <xacro:arg name="handle_ori_y" default="0.0"/>
  <joint name="handle_door" type="fixed">
    <origin xyz="0.0 0.65 0.0" rpy="0 0.0 0"/>
    <parent link="door_plane"/>
    <child link="door_handle"/>
    <axis xyz="0 0 0"/>
    <dynamics friction="0.4960139088111456"/>
    <limit lower="0.0" upper="1.57"/>
  </joint>
  <link name="door_handle">
    <visual>
      <origin xyz="0 0 0"/>
      <geometry>
        <mesh filename="handle_edited.obj" rpy="0 0 0"/>
      </geometry>
      <material name="wood">
        <color rgba="1 1 1 1"/>
      </material>
    </visual>
    <collision>
        <origin xyz="0.0 0.0 0.0" />
        <geometry>
            <mesh filename="handle_edited.obj" rpy="0 0 0" scale="1.0 1.0 1.0" />
        </geometry>
    </collision>
  </link>
</robot>
